controller-01 <179>2014-09-23T00:28:02.834276+00:00 controller-01 2014-09-23 00:28:02.832 8330 ERROR keystone.common.wsgi [-] (OperationalError) (1040, 'Too many connections') None None#0122014-09-23 00:28:02.832 8330 TRACE keystone.common.wsgi Traceback (most recent call last):#0122014-09-23 00:28:02.832 8330 TRACE keystone.common.wsgi File "/usr/lib/python2.6/site-packages/keystone/common/wsgi.py", line 387, in __call__#0122014-09-23 00:28:02.832 8330 TRACE keystone.common.wsgi response = self.process_request(request)#0122014-09-23 00:28:02.832 8330 TRACE keystone.common.wsgi File "/usr/lib/python2.6/site-packages/keystone/middleware/core.py", line 280, in process_request#0122014-09-23 00:28:02.832 8330 TRACE keystone.common.wsgi auth_context = self._build_auth_context(request)#0122014-09-23 00:28:02.832 8330 TRACE keystone.common.wsgi File "/usr/lib/python2.6/site-packages/keystone/middleware/core.py", line 251, in _build_auth_context#0122014-09-23 00:28:02.832 8330 TRACE keystone.common.wsgi token_ref = self.token_api.get_token(token_id)#0122014-09-23 00:28:02.832 8330 TRACE keystone.common.wsgi File "/usr/lib/python2.6/site-packages/keystone/token/core.py", line 141, in get_token#0122014-09-23 00:28:02.832 8330 TRACE keystone.common.wsgi token_ref = self._get_token(unique_id)#0122014-09-23 00:28:02.832 8330 TRACE keystone.common.wsgi File "/usr/lib/python2.6/site-packages/dogpile/cache/region.py", line 936, in decorate#0122014-09-23 00:28:02.832 8330 TRACE keystone.common.wsgi should_cache_fn)#0122014-09-23 00:28:02.832 8330 TRACE keystone.common.wsgi File "/usr/lib/python2.6/site-packages/dogpile/cache/region.py", line 588, in get_or_create#0122014-09-23 00:28:02.832 8330 TRACE keystone.common.wsgi async_creator) as value:#0122014-09-23 00:28:02.832 8330 TRACE keystone.common.wsgi File "/usr/lib/python2.6/site-packages/dogpile/core/dogpile.py", line 158, in __enter__#0122014-09-23 00:28:02.832 8330 TRACE keystone.common.wsgi return self._enter()#0122014-09-23 00:28:02.832 8330 TR
