controller-01 <178>2014-09-23T00:03:02.052858+00:00 controller-01 2014-09-23 00:03:02.049 25026 CRITICAL keystone [-] OperationalError: (OperationalError) (1040, 'Too many connections') None None#0122014-09-23 00:03:02.049 25026 TRACE keystone Traceback (most recent call last):#0122014-09-23 00:03:02.049 25026 TRACE keystone File "/usr/bin/keystone-manage", line 51, in <module>#0122014-09-23 00:03:02.049 25026 TRACE keystone cli.main(argv=sys.argv, config_files=config_files)#0122014-09-23 00:03:02.049 25026 TRACE keystone File "/usr/lib/python2.6/site-packages/keystone/cli.py", line 190, in main#0122014-09-23 00:03:02.049 25026 TRACE keystone CONF.command.cmd_class.main()#0122014-09-23 00:03:02.049 25026 TRACE keystone File "/usr/lib/python2.6/site-packages/keystone/cli.py", line 154, in main#0122014-09-23 00:03:02.049 25026 TRACE keystone token_manager.driver.flush_expired_tokens()#0122014-09-23 00:03:02.049 25026 TRACE keystone File "/usr/lib/python2.6/site-packages/keystone/token/backends/sql.py", line 213, in flush_expired_tokens#0122014-09-23 00:03:02.049 25026 TRACE keystone session = sql.get_session()#0122014-09-23 00:03:02.049 25026 TRACE keystone File "/usr/lib/python2.6/site-packages/keystone/common/sql/core.py", line 192, in get_session#0122014-09-23 00:03:02.049 25026 TRACE keystone return _get_engine_facade().get_session(expire_on_commit=expire_on_commit)#0122014-09-23 00:03:02.049 25026 TRACE keystone File "/usr/lib/python2.6/site-packages/keystone/common/sql/core.py", line 176, in _get_engine_facade#0122014-09-23 00:03:02.049 25026 TRACE keystone CONF.database.connection, CONF)#0122014-09-23 00:03:02.049 25026 TRACE keystone File "/usr/lib/python2.6/site-packages/keystone/openstack/common/db/sqlalchemy/session.py", line 904, in from_config#0122014-09-23 00:03:02.049 25026 TRACE keystone **dict(conf.database.items()))#0122014-09-23 00:03:02.049 25026 TRACE keystone File "/usr/lib/python2.6/site-packages/keystone/openstack/common/db/sqlalchemy/session.py", line 847, in _
