compute-02 <131>Sep 23 18:26:58 compute-02 2014-09-23 18:26:58.079 10128 ERROR oslo.messaging._drivers.impl_qpid [-] Failed to publish message to topic 'conductor': connection aborted#0122014-09-23 18:26:58.079 10128 TRACE oslo.messaging._drivers.impl_qpid Traceback (most recent call last):#0122014-09-23 18:26:58.079 10128 TRACE oslo.messaging._drivers.impl_qpid File "/usr/lib/python2.6/site-packages/oslo/messaging/_drivers/impl_qpid.py", line 546, in ensure#0122014-09-23 18:26:58.079 10128 TRACE oslo.messaging._drivers.impl_qpid return method(*args, **kwargs)#0122014-09-23 18:26:58.079 10128 TRACE oslo.messaging._drivers.impl_qpid File "/usr/lib/python2.6/site-packages/oslo/messaging/_drivers/impl_qpid.py", line 619, in _publisher_send#0122014-09-23 18:26:58.079 10128 TRACE oslo.messaging._drivers.impl_qpid publisher = cls(self.conf, self.session, topic)#0122014-09-23 18:26:58.079 10128 TRACE oslo.messaging._drivers.impl_qpid File "/usr/lib/python2.6/site-packages/oslo/messaging/_drivers/impl_qpid.py", line 407, in __init__#0122014-09-23 18:26:58.079 10128 TRACE oslo.messaging._drivers.impl_qpid super(TopicPublisher, self).__init__(conf, session, node_name)#0122014-09-23 18:26:58.079 10128 TRACE oslo.messaging._drivers.impl_qpid File "/usr/lib/python2.6/site-packages/oslo/messaging/_drivers/impl_qpid.py", line 337, in __init__#0122014-09-23 18:26:58.079 10128 TRACE oslo.messaging._drivers.impl_qpid self.reconnect(session)#0122014-09-23 18:26:58.079 10128 TRACE oslo.messaging._drivers.impl_qpid File "/usr/lib/python2.6/site-packages/oslo/messaging/_drivers/impl_qpid.py", line 341, in reconnect#0122014-09-23 18:26:58.079 10128 TRACE oslo.messaging._drivers.impl_qpid self.sender = session.sender(self.address)#0122014-09-23 18:26:58.079 10128 TRACE oslo.messaging._drivers.impl_qpid File "<string>", line 6, in sender#0122014-09-23 18:26:58.079 10128 TRACE oslo.messaging._drivers.impl_qpid File "/usr/lib/python2.6/site-packages/qpid/messaging/endpoints.py", line 597, in sender#0122014-09-23 18:2
