controller-01 <131>2014-09-23T18:13:06.394290+00:00 controller-01 2014-09-23 18:13:06.392 8916 ERROR nova.api.openstack [req-8fff97ce-ef46-4a1e-94be-cd93b1e4d7c3 f5734077b04d4f9f95cb8fec7699f6f8 3aa3b6e4ce0048a7997d900ddde95d41] Caught error: (OperationalError) (1040, 'Too many connections') None None#0122014-09-23 18:13:06.392 8916 TRACE nova.api.openstack Traceback (most recent call last):#0122014-09-23 18:13:06.392 8916 TRACE nova.api.openstack File "/usr/lib/python2.6/site-packages/nova/api/openstack/__init__.py", line 125, in __call__#0122014-09-23 18:13:06.392 8916 TRACE nova.api.openstack return req.get_response(self.application)#0122014-09-23 18:13:06.392 8916 TRACE nova.api.openstack File "/usr/lib/python2.6/site-packages/webob/request.py", line 1296, in send#0122014-09-23 18:13:06.392 8916 TRACE nova.api.openstack application, catch_exc_info=False)#0122014-09-23 18:13:06.392 8916 TRACE nova.api.openstack File "/usr/lib/python2.6/site-packages/webob/request.py", line 1260, in call_application#0122014-09-23 18:13:06.392 8916 TRACE nova.api.openstack app_iter = application(self.environ, start_response)#0122014-09-23 18:13:06.392 8916 TRACE nova.api.openstack File "/usr/lib/python2.6/site-packages/webob/dec.py", line 144, in __call__#0122014-09-23 18:13:06.392 8916 TRACE nova.api.openstack return resp(environ, start_response)#0122014-09-23 18:13:06.392 8916 TRACE nova.api.openstack File "/usr/lib/python2.6/site-packages/keystoneclient/middleware/auth_token.py", line 679, in __call__#0122014-09-23 18:13:06.392 8916 TRACE nova.api.openstack return self.app(env, start_response)#0122014-09-23 18:13:06.392 8916 TRACE nova.api.openstack File "/usr/lib/python2.6/site-packages/webob/dec.py", line 144, in __call__#0122014-09-23 18:13:06.392 8916 TRACE nova.api.openstack return resp(environ, start_response)#0122014-09-23 18:13:06.392 8916 TRACE nova.api.openstack File "/usr/lib/python2.6/site-packages/webob/dec.py", line 144, in __call__#0122014-09-23 18:13:06.392 8916 TRACE nova.api.openstack
