controller-01 <131>2014-09-23T18:26:58.081256+00:00 controller-01 2014-09-23 18:26:58.054 8642 ERROR oslo.messaging._drivers.impl_qpid [-] Failed to consume message from queue: connection aborted#0122014-09-23 18:26:58.054 8642 TRACE oslo.messaging._drivers.impl_qpid Traceback (most recent call last):#0122014-09-23 18:26:58.054 8642 TRACE oslo.messaging._drivers.impl_qpid File "/usr/lib/python2.6/site-packages/oslo/messaging/_drivers/impl_qpid.py", line 546, in ensure#0122014-09-23 18:26:58.054 8642 TRACE oslo.messaging._drivers.impl_qpid return method(*args, **kwargs)#0122014-09-23 18:26:58.054 8642 TRACE oslo.messaging._drivers.impl_qpid File "/usr/lib/python2.6/site-packages/oslo/messaging/_drivers/impl_qpid.py", line 599, in _consume#0122014-09-23 18:26:58.054 8642 TRACE oslo.messaging._drivers.impl_qpid nxt_receiver = self.session.next_receiver(timeout=timeout)#0122014-09-23 18:26:58.054 8642 TRACE oslo.messaging._drivers.impl_qpid File "<string>", line 6, in next_receiver#0122014-09-23 18:26:58.054 8642 TRACE oslo.messaging._drivers.impl_qpid File "/usr/lib/python2.6/site-packages/qpid/messaging/endpoints.py", line 665, in next_receiver#0122014-09-23 18:26:58.054 8642 TRACE oslo.messaging._drivers.impl_qpid if self._ecwait(lambda: self.incoming, timeout):#0122014-09-23 18:26:58.054 8642 TRACE oslo.messaging._drivers.impl_qpid File "/usr/lib/python2.6/site-packages/qpid/messaging/endpoints.py", line 50, in _ecwait#0122014-09-23 18:26:58.054 8642 TRACE oslo.messaging._drivers.impl_qpid result = self._ewait(lambda: self.closed or predicate(), timeout)#0122014-09-23 18:26:58.054 8642 TRACE oslo.messaging._drivers.impl_qpid File "/usr/lib/python2.6/site-packages/qpid/messaging/endpoints.py", line 571, in _ewait#0122014-09-23 18:26:58.054 8642 TRACE oslo.messaging._drivers.impl_qpid result = self.connection._ewait(lambda: self.error or predicate(), timeout)#0122014-09-23 18:26:58.054 8642 TRACE oslo.messaging._drivers.impl_qpid File "/usr/lib/python2.6/site-packages/qpid/messaging/endpoints.py
